Workbook

Sheet Raw Data (Messy)
A1: RAW DATA — AS RECEIVED (contains real-world data quality issues)
A3: OrderID | B3: Date | C3: Product | D3: Category | E3: Region | F3: SalesRep | G3: Quantity | H3: UnitPrice
A4: ORD1101 | B4: 15-Jan-2024 | C4: usb-c hub | D4: Accessories | E4: West | G4: 14 | H4: 1299
A5: ORD1577 | B5: 2024-03-29 00:00:00 | C5: Mechanical Keyboard | D5: Accessories | E5: North | F5: Karan Mehta | G5: 1 | H5: 2499
A6: ORD1409 | B6: 2024-04-02 00:00:00 | C6: Desk Lamp | D6: Furniture | E6: South | F6: Sneha Patel | G6: 14 | H6: 699
A7: ORD1499 | B7: 2024-01-11 00:00:00 | C7: Laptop Stand | D7: Furniture | E7: South | F7: Priya Singh | H7: 899
A8: ORD1224 | B8: 2024-01-23 00:00:00 | C8: Power Bank | D8: Electronics | E8: West | F8: Karan Mehta | G8: 12 | H8: 1499
A9: ORD1340 | B9: 2024-10-13 00:00:00 | C9: Laptop Stand | D9: Furniture | E9: South | F9: Rohit Verma | G9: 13 | H9: 899
A10: ORD1482 | B10: 2024-05-12 00:00:00 | C10: Webcam HD | D10: Electronics | E10: West | F10: Karan Mehta | G10: 2 | H10: 1999
A11: ORD1041 | B11: 2024-10-29 00:00:00 | C11: Desk Lamp | D11: Furniture | E11: East | F11: Amit Sharma | G11: 12 | H11: 699
A12: ORD1047 | B12: 2024-02-19 00:00:00 | C12: Wireless Mouse | D12: Accessories | E12: South | F12: Sneha Patel | H12: 499
A13: ORD1553 | B13: 2024-08-02 00:00:00 | C13: Wireless Mouse | D13: Accessories | E13: WEST | F13: Karan Mehta | G13: 11 | H13: 499
A14: ORD1603 | B14: 2024-05-29 00:00:00 | C14: Laptop Stand | D14: Furniture | E14: South | F14: Rohit Verma | G14: 14 | H14: 899
A15: ORD1521 | B15: 2024-01-06 00:00:00 | C15: Wireless Mouse | D15: Accessories | E15: West | F15: Priya Singh | G15: 10 | H15: 499
A16: ORD1292 | B16: 2024-09-13 00:00:00 | C16: Cable Organizer | D16: Accessories | E16: North | F16: Amit Sharma | G16: 3 | H16: 299
A17: ORD1069 | B17: 2024-10-20 00:00:00 | C17: Power Bank | D17: Electronics | E17: North | F17: Priya Singh | G17: 12 | H17: 1499
A18: ORD1610 | B18: 2024-08-10 00:00:00 | C18: Desk Lamp | D18: Furniture | E18: South | F18: Amit Sharma | G18: 11 | H18: 699
A19: ORD1233 | B19: 2024-09-25 00:00:00 | C19: Cable Organizer | D19: Accessories | E19: East | F19: Sneha Patel | G19: 12 | H19: 299
A20: ORD1632 | B20: 2024-07-21 00:00:00 | C20: Mechanical Keyboard | D20: Accessories | E20: South | F20: Amit Sharma | G20: 13 | H20: 2499
A21: ORD1023 | B21: 2024-05-14 00:00:00 | C21: Desk Lamp | D21: Furniture | E21: East | F21: Sneha Patel | G21: 11 | H21: 699
A22: ORD1551 | B22: 2024-06-28 00:00:00 | C22: Cable Organizer | D22: Accessories | E22: North | F22: Rohit Verma | G22: 13 | H22: 299
A23: ORD1013 | B23: 2024-10-02 00:00:00 | C23: Mechanical Keyboard | D23: Accessories | E23: West | F23: Priya Singh | G23: 6 | H23: 2499
A24: ORD1475 | B24: 2024-07-09 00:00:00 | C24: Power Bank | D24: Electronics | E24: East | F24: Sneha Patel | G24: 2 | H24: 1499
... A47: ORD1165 | B47: 2024-05-09 00:00:00 | C47: Wireless Mouse | D47: Accessories | E47: North | F47: Rohit Verma | G47: 8 | H47: 499
A48: ORD1371 | B48: 2024-12-04 00:00:00 | C48: Power Bank | D48: Electronics | E48: North | F48: Amit Sharma | H48: 1499
A49: ORD1034 | B49: 2024-09-26 00:00:00 | C49: Bluetooth Speaker | D49: Electronics | E49: West | F49: Priya Singh | G49: 1 | H49: 1799
A50: ORD1200 | B50: 2024-08-27 00:00:00 | C50: Cable Organizer | D50: Accessories | E50: East | F50: Karan Mehta | G50: 7 | H50: 299
A51: ORD1181 | B51: 2024-06-12 00:00:00 | C51: USB-C Hub | D51: Accessories | E51: East | F51: Priya Singh | G51: 7 | H51: 1299
A52: ORD1363 | B52: 2024-05-10 00:00:00 | C52: Laptop Stand | D52: Furniture | E52: West | F52: Karan Mehta | G52: 9 | H52: 899
A53: ORD1504 | B53: 2024-01-04 00:00:00 | C53: USB-C Hub | D53: Accessories | E53: East | F53: Rohit Verma | G53: 1 | H53: 1299
A54: ORD1589 | B54: 2024-08-31 00:00:00 | C54: Monitor 24in | D54: Electronics | E54: North | F54: Amit Sharma | G54: 3 | H54: 8999
A55: ORD1159 | B55: 2024-05-09 00:00:00 | C55: USB-C Hub | D55: Accessories | E55: East | F55: Priya Singh | G55: 8 | H55: 1299
A56: ORD1419 | B56: 2024-04-05 00:00:00 | C56: Cable Organizer | D56: Accessories | E56: East | F56: Karan Mehta | G56: 7 | H56: 299
A57: ORD1088 | B57: 2024-08-02 00:00:00 | C57: Monitor 24in | D57: Electronics | E57: North | F57: Sneha Patel | G57: 12 | H57: 8999
A58: ORD1107 | B58: 2024-01-28 00:00:00 | C58: Laptop Stand | D58: Furniture | E58: East | F58: Karan Mehta | G58: 10 | H58: 899
A59: ORD1201 | B59: 2024-04-05 00:00:00 | C59: Webcam HD | D59: Electronics | E59: south | F59: Karan Mehta | G59: 5 | H59: 1999
A60: ORD1526 | B60: 2024-05-29 00:00:00 | C60: USB-C Hub | D60: Accessories | E60: West | F60: Priya Singh | G60: 10 | H60: 1299
... A64: ORD1426 | B64: 2024-06-22 00:00:00 | C64: Laptop Stand | D64: Furniture | E64: West | F64: Karan Mehta | G64: 2 | H64: 899
A65: ORD1406 | B65: 2024-05-07 00:00:00 | C65: Laptop Stand | D65: Furniture | E65: West | F65: Priya Singh | G65: 12
A66: ORD1506 | B66: 2024-01-17 00:00:00 | C66: Monitor 24in | D66: Electronics | E66: South | F66: Amit Sharma | G66: 7 | H66: 8999
...

Sheet Data Cleaning Log
B2: DATA CLEANING PROCESS
B3: Documented steps taken to clean the raw dataset before analysis
B5: Step | C5: Action Taken
B6: 1 | C6: Starting rows: 635
B7: 2 | C7: Dates standardized to YYYY-MM-DD. Unparseable dates: 0
B8: 3 | C8: Trimmed whitespace and standardized casing in Product (canonical map), Category, Region, SalesRep
B9: 4 | C9: Removed 15 duplicate transaction entries
B10: 5 | C10: Corrected 6 negative quantity entries (data entry errors) to positive
B11: 6 | C11: Filled 18 missing Quantity values using category median
B12: 7 | C12: Filled 12 missing UnitPrice values using product-level median price
B13: 8 | C13: Labeled 8 missing SalesRep entries as 'Unassigned' (kept rows, revenue still counted)
B14: 9 | C14: Final clean rows: 620
B17: BEFORE vs AFTER
B18: Metric | C18: Raw Data | D18: Clean Data
B19: Total Rows | C19: 635 | D19: 620
B20: Missing Quantity | C20: 18 | D20: 0
B21: Missing UnitPrice | C21: 12 | D21: 0
B22: Missing SalesRep | C22: 8 | D22: 0
B23: Duplicate Transactions | C23: 15 | D23: 0
B24: Negative Quantity Errors | C24: 6 | D24: 0

Sheet Clean Data
A1: OrderID | B1: Date | C1: Product | D1: Category | E1: Region | F1: SalesRep | G1: Quantity | H1: UnitPrice | I1: TotalSale
A2: ORD1086 | B2: 2024-01-01 | C2: Wireless Mouse | D2: Accessories | E2: East | F2: Sneha Patel | G2: 8 | H2: 499 | I2: =G2*H2 -> 3992
A3: ORD1100 | B3: 2024-01-01 | C3: USB-C Hub | D3: Accessories | E3: South | F3: Priya Singh | G3: 3 | H3: 1299 | I3: =G3*H3 -> 3897
A4: ORD1154 | B4: 2024-01-01 | C4: Cable Organizer | D4: Accessories | E4: North | F4: Amit Sharma | G4: 12 | H4: 299 | I4: =G4*H4 -> 3588
A5: ORD1003 | B5: 2024-01-01 | C5: Monitor 24in | D5: Electronics | E5: East | F5: Sneha Patel | G5: 13 | H5: 8999 | I5: =G5*H5 -> 116987
A6: ORD1573 | B6: 2024-01-01 | C6: Wireless Mouse | D6: Accessories | E6: South | F6: Amit Sharma | G6: 3 | H6: 499 | I6: =G6*H6 -> 1497
A7: ORD1126 | B7: 2024-01-01 | C7: Bluetooth Speaker | D7: Electronics | E7: East | F7: Priya Singh | G7: 7 | H7: 1799 | I7: =G7*H7 -> 12593
A8: ORD1495 | B8: 2024-01-04 | C8: Webcam HD | D8: Electronics | E8: North | F8: Rohit Verma | G8: 8 | H8: 1999 | I8: =G8*H8 -> 15992
A9: ORD1225 | B9: 2024-01-04 | C9: Cable Organizer | D9: Accessories | E9: South | F9: Priya Singh | G9: 9 | H9: 299 | I9: =G9*H9 -> 2691
A10: ORD1504 | B10: 2024-01-04 | C10: USB-C Hub | D10: Accessories | E10: East | F10: Rohit Verma | G10: 1 | H10: 1299 | I10: =G10*H10 -> 1299
A11: ORD1112 | B11: 2024-01-05 | C11: Cable Organizer | D11: Accessories | E11: South | F11: Sneha Patel | G11: 6 | H11: 299 | I11: =G11*H11 -> 1794
A12: ORD1443 | B12: 2024-01-05 | C12: Laptop Stand | D12: Furniture | E12: South | F12: Sneha Patel | G12: 12 | H12: 899 | I12: =G12*H12 -> 10788
A13: ORD1025 | B13: 2024-01-06 | C13: Mechanical Keyboard | D13: Accessories | E13: East | F13: Karan Mehta | G13: 10 | H13: 2499 | I13: =G13*H13 -> 24990
... A621: ORD1493 | B621: 2024-12-31 | C621: Mechanical Keyboard | D621: Accessories | E621: North | F621: Priya Singh | G621: 1 | H621: 2499 | I621: =G621*H621 -> 2499

Sheet Summary Dashboard
B2: Retail Sales Analysis — FY 2024 (Post-Cleaning)
B3: Portfolio Project | Data Cleaning + Analysis | Excel
B5: KEY METRICS
B6: Total Revenue | C6: =SUM('Clean Data'!I2:I621) -> 9261406
B7: Total Orders | C7: =COUNTA('Clean Data'!A2:A621) -> 620
B8: Avg Order Value | C8: =C6/C7 -> 14937.752
B9: Total Units Sold | C9: =SUM('Clean Data'!G2:G621) -> 4594
B10: REVENUE BY CATEGORY | E10: REVENUE BY REGION | H10: REVENUE BY SALES REP
B11: Category | C11: Revenue | E11: Region | F11: Revenue | H11: Sales Rep | I11: Revenue
B12: Accessories | C12: =SUMIFS('Clean Data'!$I$2:$I$621,'Clean Data'!$D$2:$D$621,B12) -> 2134961 | E12: East | F12: =SUMIFS('Clean Data'!$I$2:$I$621,'Clean Data'!$E$2:$E$621,E12) -> 2372143 | H12: Amit Sharma | I12: =SUMIFS('Clean Data'!$I$2:$I$621,'Clean Data'!$F$2:$F$621,H12) -> 2508447
B13: Electronics | C13: =SUMIFS('Clean Data'!$I$2:$I$621,'Clean Data'!$D$2:$D$621,B13) -> 6386543 | E13: North | F13: =SUMIFS('Clean Data'!$I$2:$I$621,'Clean Data'!$E$2:$E$621,E13) -> 2480769 | H13: Karan Mehta | I13: =SUMIFS('Clean Data'!$I$2:$I$621,'Clean Data'!$F$2:$F$621,H13) -> 1177957
B14: Furniture | C14: =SUMIFS('Clean Data'!$I$2:$I$621,'Clean Data'!$D$2:$D$621,B14) -> 739902 | E14: South | F14: =SUMIFS('Clean Data'!$I$2:$I$621,'Clean Data'!$E$2:$E$621,E14) -> 2341769 | H14: Priya Singh | I14: =SUMIFS('Clean Data'!$I$2:$I$621,'Clean Data'!$F$2:$F$621,H14) -> 1620011
E15: West | F15: =SUMIFS('Clean Data'!$I$2:$I$621,'Clean Data'!$E$2:$E$621,E15) -> 2066725 | H15: Rohit Verma | I15: =SUMIFS('Clean Data'!$I$2:$I$621,'Clean Data'!$F$2:$F$621,H15) -> 1827283
H16: Sneha Patel | I16: =SUMIFS('Clean Data'!$I$2:$I$621,'Clean Data'!$F$2:$F$621,H16) -> 1869685
H17: Unassigned | I17: =SUMIFS('Clean Data'!$I$2:$I$621,'Clean Data'!$F$2:$F$621,H17) -> 258023
B21: REVENUE BY PRODUCT
B22: Product | C22: Revenue
B23: Bluetooth Speaker | C23: =SUMIFS('Clean Data'!$I$2:$I$621,'Clean Data'!$C$2:$C$621,B23) -> 919289
B24: Cable Organizer | C24: =SUMIFS('Clean Data'!$I$2:$I$621,'Clean Data'!$C$2:$C$621,B24) -> 126477
B25: Desk Lamp | C25: =SUMIFS('Clean Data'!$I$2:$I$621,'Clean Data'!$C$2:$C$621,B25) -> 235563
B26: Laptop Stand | C26: =SUMIFS('Clean Data'!$I$2:$I$621,'Clean Data'!$C$2:$C$621,B26) -> 504339
B27: Mechanical Keyboard | C27: =SUMIFS('Clean Data'!$I$2:$I$621,'Clean Data'!$C$2:$C$621,B27) -> 1129548
B28: Monitor 24in | C28: =SUMIFS('Clean Data'!$I$2:$I$621,'Clean Data'!$C$2:$C$621,B28) -> 4067548
B29: Power Bank | C29: =SUMIFS('Clean Data'!$I$2:$I$621,'Clean Data'!$C$2:$C$621,B29) -> 562125
B30: USB-C Hub | C30: =SUMIFS('Clean Data'!$I$2:$I$621,'Clean Data'!$C$2:$C$621,B30) -> 565065
B31: Webcam HD | C31: =SUMIFS('Clean Data'!$I$2:$I$621,'Clean Data'!$C$2:$C$621,B31) -> 837581
B32: Wireless Mouse | C32: =SUMIFS('Clean Data'!$I$2:$I$621,'Clean Data'!$C$2:$C$621,B32) -> 313871

Sheet Monthly Trend
B2: MONTHLY REVENUE TREND
B3: Month | C3: Revenue
B4: Jan | C4: =SUMPRODUCT((TEXT('Clean Data'!$B$2:$B$621,"YYYY-MM")="2024-01")*'Clean Data'!$I$2:$I$621) -> 921922
B5: Feb | C5: =SUMPRODUCT((TEXT('Clean Data'!$B$2:$B$621,"YYYY-MM")="2024-02")*'Clean Data'!$I$2:$I$621) -> 673239
B6: Mar | C6: =SUMPRODUCT((TEXT('Clean Data'!$B$2:$B$621,"YYYY-MM")="2024-03")*'Clean Data'!$I$2:$I$621) -> 946322
B7: Apr | C7: =SUMPRODUCT((TEXT('Clean Data'!$B$2:$B$621,"YYYY-MM")="2024-04")*'Clean Data'!$I$2:$I$621) -> 945430
B8: May | C8: =SUMPRODUCT((TEXT('Clean Data'!$B$2:$B$621,"YYYY-MM")="2024-05")*'Clean Data'!$I$2:$I$621) -> 715642
B9: Jun | C9: =SUMPRODUCT((TEXT('Clean Data'!$B$2:$B$621,"YYYY-MM")="2024-06")*'Clean Data'!$I$2:$I$621) -> 601016
B10: Jul | C10: =SUMPRODUCT((TEXT('Clean Data'!$B$2:$B$621,"YYYY-MM")="2024-07")*'Clean Data'!$I$2:$I$621) -> 746642
B11: Aug | C11: =SUMPRODUCT((TEXT('Clean Data'!$B$2:$B$621,"YYYY-MM")="2024-08")*'Clean Data'!$I$2:$I$621) -> 896131
B12: Sep | C12: =SUMPRODUCT((TEXT('Clean Data'!$B$2:$B$621,"YYYY-MM")="2024-09")*'Clean Data'!$I$2:$I$621) -> 660964
B13: Oct | C13: =SUMPRODUCT((TEXT('Clean Data'!$B$2:$B$621,"YYYY-MM")="2024-10")*'Clean Data'!$I$2:$I$621) -> 824132
B14: Nov | C14: =SUMPRODUCT((TEXT('Clean Data'!$B$2:$B$621,"YYYY-MM")="2024-11")*'Clean Data'!$I$2:$I$621) -> 542940
B15: Dec | C15: =SUMPRODUCT((TEXT('Clean Data'!$B$2:$B$621,"YYYY-MM")="2024-12")*'Clean Data'!$I$2:$I$621) -> 787026
